Workbook

Sheet 成本汇总-测算主表
A1: 超大型土石方开挖运输成本测算表
A3: 【岩石选择】
A4: 岩石级别 | B4: Ⅰ极软岩 | C4: 下拉选择岩石级别（Ⅰ~Ⅷ），自动匹配对应参数
A5: 普氏系数f | B5: =IFERROR(VLOOKUP(B4,'基础核心-参数库'!$E$3:$F$10,2,0),5) | C5: 数据来源: GB/T 50218-2014《工程岩体分级标准》普氏系数f = 岩石单轴抗压强度(MPa) ÷ 10
A6: 实体容重(t/m³) | B6: =IFERROR(VLOOKUP(B4,'基础核心-参数库'!$E$3:$G$10,3,0),2.45) | C6: 数据来源: 岩石力学手册/现场实测实体容重 = 岩石密度 × 重力加速度，取值2.3~2.7 t/m³
A7: 松散系数 | B7: =IFERROR(VLOOKUP(B4,'基础核心-参数库'!$E$3:$H$10,4,0),1.42) | C7: 数据来源: 土石方工程定额实测松散系数 = 松散后体积 ÷ 天然密实体积，取值1.1~1.5
A8: 大块率 | B8: =IFERROR(VLOOKUP(B4,'基础核心-参数库'!$E$3:$K$10,7,0),0.1) | C8: 数据来源: 爆破工程经验统计大块率 = 块径>30cm的体积占比，f越大大块率越高
A9: 可预裂 | B9: =IFERROR(VLOOKUP(B4,'基础核心-参数库'!$E$3:$L$10,8,0),"是") | C9: 判断逻辑: Ⅴ级及以上硬岩才需要预裂爆破预裂目的: 保护边坡稳定性，减少超欠挖
A11: 【工艺选择】
A12: 工艺选择 | B12: 直接开挖 | C12: 推荐工艺仅供参考，可手动选择其他工艺对比成本
A13: 推荐工艺 | B13: =IFERROR(VLOOKUP(B4,'基础核心-参数库'!$E$3:$I$10,5,0),"爆破+开挖") | C13: 推荐逻辑: f≤2→直接开挖，f≤5→爆破+开挖，f>5→爆破+二次破碎
A14: 工艺-岩石硬度匹配校验 | B14: =IF(AND(B5>6,B12="直接开挖"),"⚠极硬岩不宜直接开挖",IF(AND(B5<2,B12="爆破+开挖"),"⚠极软岩不宜爆破,请选直接开挖或松土器","✅")) | C14: f>6直接开挖 → 警告，f<2爆破开挖 → 警告。
A16: 【挖装设备选择】
A17: 挖机选择 | B17: W4.5
A18: 挖机来源 | B18: 自有
A19: 推荐挖机 | B19: =IFERROR(INDEX('合理建议表-推荐规则'!$D$3:$D$8,MATCH(B5,'合理建议表-推荐规则'!$A$3:$A$8,1)),"W4.5") | C19: 推荐逻辑: f=1~3→W3.2/W4.5, f=5~8→W5.5挖机斗容与岩石硬度正相关
A21: 【运输设备选择】
A22: 推荐矿卡 | B22: {=IF(OR(B37="下坡",B39="下坡"),"推荐纯电："&IFERROR(INDEX('合理建议表-推荐规则'!$J$3:$J$8,MATCH(B5,'合理建议表-推荐规则'!$A$3:$A$8,1)),""),"推荐柴油："&IFERROR(INDEX('合理建议表-推荐规则'!$K$3:$K$8,MATCH(B5,'合理建议表-推荐规则'!$A$3:$A$8,1)),""))} | C22: 运距≤3km→T65B(短中途), 运距>8km→T91B(长途); 电动条件下推荐E60Y/E75T/E93L
A23: 矿卡选择 | B23: T65B | C23: 代号规则：T=柴油/E=纯电 + 载重吨位 + 品牌首字母。
A24: 矿卡来源 | B24: 自有
A25: 矿卡与运距选择匹配度 | B25: =IF(AND(B36>10,IFERROR(VLOOKUP(B23,'基础核心-参数库'!$A$40:$D$47,4,0),0)<60),"⚠运距长矿卡偏小",IF(AND(B36<3,IFERROR(VLOOKUP(B23,'基础核心-参数库'!$A$40:$D$47,4,0),0)>60),"⚠矿卡偏大不经济","✅")) | C25: 运距>10km矿卡<60t → 警告，运距<3km矿卡>60t → 警告
A27: 【钻孔设备选择】
A28: 推荐钻机 | B28: =IF(AND(B47>15),"KY200",IF(OR(B12="爆破+开挖",B12="爆破+二次破碎+开挖"),IFERROR(INDEX('合理建议表-推荐规则'!$H$3:$H$8,MATCH(B5,'合理建议表-推荐规则'!$A$3:$A$8,1)),"ZG90"),"—")) | C28: 推荐逻辑: f≤3→ZG90, f≤5→ZG120, f>5→ZG150/牙轮硬岩需要更大扭矩钻机。
A29: 钻机选择 | B29: ZG90
A30: 钻机来源 | B30: 自有
A31: 钻机型号-台阶高度匹配校验 | B31: =IF(AND(B47>15,IFERROR(VLOOKUP(B29,'基础核心-参数库'!$A$51:$O$58,15,0),"潜孔")="潜孔"),"⚠台阶>15m宜选用牙轮钻机(KY200/KY250)","✅") | C31: 钻机选择与台阶高度匹配度：台阶>15m用中小型钻机 → 警告
A33: 【运输参数选择】
A34: 场内距离(km) | B34: 2.1
A35: 场外距离(km) | B35: 5
A36: 总运距(km) | B36: =B34+B35 | C36: 经济运距: 自卸车合理运距≤5km，超过考虑皮带/铁路。场内倒运一般0.5~2km
A37: 场内重车方向 | B37: 平路 | C37: 选择平路则坡度应在2%，上下坡坡度应在15%以内。
A38: 场内坡度(%) | B38: 1.5
A39: 场外重车方向 | B39: 平路 | C39: 选择平路则坡度应在2%，上下坡坡度应在15%以内。
A40: 场外坡度(%) | B40: 1
A41: 道路坡度-行驶方向匹配校验 | B41: =IF(AND(B37="平路",B38>2),"⚠平路场内坡度应≤2%",IF(AND(B37<>"平路",B38<2),"⚠上/下坡场内坡度应≥2%",IF(B38>15,"⚠场内坡度>15%",IF(AND(B39="平路",B40>2),"⚠平路场外坡度应≤2%",IF(AND(B39<>"平路",B40<2),"⚠上/下场外坡度应≥2%",IF(B40>15,"⚠场外坡度>15%","✅")))))) | C41: 坡度与方向匹配度：平路坡度>2% → 警告，上下坡坡度<2% → 警告
A43: 【爆破设计参数规划】
A44: 爆破区域长度(m) | B44: 50 | C44: 沿台阶走向的一次爆破长度，用于分摊预裂费用
A45: 爆破区域宽度(m) | B45: 20 | C45: 从预裂孔到最后排主爆孔的总深度
A46: 缓冲孔排数 | B46: 1 | C46: 预裂爆破时在预裂孔后方设置的缓冲孔排数
A47: 台阶高度H(m) | B47: 10 | C47: 合理范围: 5~15m，推荐8~12m台阶太高→安全风险，太低→施工效率低
...

Sheet 基础核心-参数库
A1: 【基础价格参数】 | D1: 【岩石分类及开采工艺规则】 | M1: 【工艺错配惩罚系数表】 | Y1: 【通用常量区】
A2: 参数名称 | B2: 数值 | C2: 单位 | D2: 岩石名称 | E2: 岩石级别 | F2: 普氏系数f | G2: 实体容重(t/m³) | H2: 松散系数 | I2: 推荐工艺 | J2: 其他可选工艺 | K2: 爆破大块率 | L2: 可预裂 | M2: 偏离类型 | N2: 效率折减 | O2: 耗材费倍率 | Y2: 参数名称 | Z2: 数值 | AA2: 说明/备注
A3: 柴油单价 | B3: 7.5 | C3: 元/L | D3: 全风化花岗岩 | E3: Ⅰ极软岩 | F3: 0.5 | G3: 1.75 | H3: 1.15 | I3: 直接开挖 | J3: 松土器松土+开挖 | K3: 0 | L3: 否 | M3: 爆破→松土 | N3: 0.2 | O3: 3 | Y3: 矿用运输车折旧维修系数 | Z3: 1.3 | AA3: 运输B68：露天矿1.3~1.8（含日常保养+二级维护）；井下/恶劣矿2.5 | 矿卡折旧维修系数（合同校准）：露天精益承包商下限
A4: 电价(平均) | B4: 0.65 | C4: 元/kWh | D4: 泥岩 | E4: Ⅱ软岩 | F4: 1.5 | G4: 2.1 | H4: 1.25 | I4: 松土器松土+开挖 | J4: 直接开挖,机械破碎+开挖 | K4: 0 | L4: 否 | M4: 爆破→破碎 | N4: 0.5 | O4: 2 | Y4: 挖掘机折旧维修系数 | Z4: 1.5 | AA4: 挖装B28：含液压系统大修+磨耗件，露天1.5~1.8 | 挖掘机折旧维修系数（合同校准）：露天典型中位
A5: 司机机手工日单价 | B5: 300 | C5: 元/工日 | D5: 强风化砂岩 | E5: Ⅲ较软岩 | F5: 3 | G5: 2.3 | H5: 1.35 | I5: 松土器松土+开挖 | J5: 直接开挖,机械破碎+开挖,爆破+开挖 | K5: 0 | L5: 否 | M5: 松土→爆破 | N5: 1 | O5: 1 | Y5: 钻机折旧维修系数 | Z5: 2.2 | AA5: 钻爆B94：钻头钻杆消耗大，系数稍高，1.6~2.0
A6: 乳化炸药单价 | B6: 12 | C6: 元/kg | D6: 中等风化砂岩 | E6: Ⅳ中硬岩 | F6: 5 | G6: 2.45 | H6: 1.42 | I6: 爆破+开挖 | J6: 松土器松土+开挖,机械破碎+开挖,爆破+二次破碎+开挖 | K6: 0.1 | L6: 是 | M6: 松土→破碎 | N6: 0.7 | O6: 1.5 | Y6: 装载机折旧维修系数 | Z6: 1.8 | AA6: 钻爆B11：爆破辅助装载机，1.3~1.8
A7: 雷管单价(数码雷管) | B7: 14 | C7: 元/发 | D7: 微风化花岗岩 | E7: Ⅴ较硬岩 | F7: 7 | G7: 2.6 | H7: 1.48 | I7: 爆破+开挖 | J7: 机械破碎+开挖,爆破+二次破碎+开挖 | K7: 0.12 | L7: 是 | M7: 松土→直接开挖 | N7: 1 | O7: 1 | Y7: 平路油耗负载因子 | Z7: 0.15 | AA7: 运输B59/B61：平路油耗=空车+(上坡-空车)×此值；硬质路0.20，一般0.25，松软0.30 | 平路油耗负载因子（合同校准）：硬质矿山路面
A8: 导爆索单价 | B8: 3 | C8: 元/m | D8: 新鲜花岗岩 | E8: Ⅵ坚硬岩 | F8: 10 | G8: 2.7 | H8: 1.54 | I8: 爆破+开挖 | J8: 爆破+二次破碎+开挖 | K8: 0.18 | L8: 是 | Y8: 矿用车辆耐用年限 | Z8: 8 | AA8: 年；联动矿卡区L40~L47耐用台班=250×此值
A9: 破碎锤钎杆单价 | B9: 1200 | C9: 元/根 | D9: 玄武岩 | E9: Ⅶ极硬岩 | F9: 16 | G9: 2.85 | H9: 1.6 | I9: 爆破+开挖 | J9: 爆破+二次破碎+开挖 | K9: 0.25 | L9: 是 | Y9: 挖掘机耐用年限 | Z9: 10 | AA9: 年；挖机区K26耐用台班=250×此值（K27~K36为型号特异值）
A10: 破碎锤钎杆寿命 | B10: 800 | C10: m³实方 | D10: 致密石英岩 | E10: Ⅷ特殊坚硬岩 | F10: 20 | G10: 3 | H10: 1.65 | I10: 爆破+开挖 | J10: 爆破+二次破碎+开挖 | K10: 0.3 | L10: 是 | Y10: 台班小时数 | Z10: 8 | AA10: h/台班，行业标准（一班制8h，二班制16h）
A11: 渣场维护费 | B11: 0.5 | C11: 元/m³实方 | D11: 【f值相关参数插值基准点】 | Y11: 柴油机械时间利用率 | Z11: 0.75 | AA11: 运输B17、挖装B14、钻爆B93共用；含怠速空驶等无效时间
A12: 松土器齿尖单价 | B12: 600 | C12: 元/个 | D12: 普氏系数f | E12: 钻孔速度系数 | F12: 爆破单耗(kg/m³) | G12: 挖机满斗系数(已弃用) | H12: 松土器效率系数 | I12: 破碎锤效率系数 | J12: 直接开挖折减系数(已弃用) | K12: W1/H系数 | L12: 超深系数 | Y12: 电动机械时间利用率 | Z12: 0.85 | AA12: 电动设备工况系数；同上三处共用
A13: 松土器齿尖寿命 | B13: 2000 | C13: m³实方 | D13: 0.5 | E13: 2.5 | F13: 0 | G13: 0.95 | H13: 2 | I13: 1.2 | J13: 0.95 | K13: 0.9 | L13: 0.12 | Y13: 矿卡时间利用率 | Z13: 0.85 | AA13: 运输B50；含调度/装车排队等待，露天矿0.80~0.90
A14: 机油/液压油单价 | B14: 20 | C14: 元/L | D14: 1 | E14: 2.1 | F14: 0.35 | G14: 0.92 | H14: 1.8 | I14: 1.15 | J14: 0.9 | K14: 0.88 | L14: 0.14 | Y14: 挖机时间利用率 | Z14: 0.75 | AA14: 挖装B22；等车占比最大，露天矿0.75~0.85 | 挖机时间利用率（合同校准）：露天合理上限
A15: 黄油单价 | B15: 15 | C15: 元/kg | D15: 2 | E15: 1.8 | F15: 0.4 | G15: 0.88 | H15: 1.5 | I15: 1.05 | J15: 0.8 | K15: 0.85 | L15: 0.16 | Y15: 钻机时间利用率 | Z15: 0.75 | AA15: 钻爆B87；含换杆/移位/钻头更换，0.65~0.80
A16: 爆破工日工资 | B16: 500 | C16: 元/工日 | D16: 4 | E16: 1.4 | F16: 0.45 | G16: 0.85 | H16: 1 | I16: 0.95 | J16: 0.55 | K16: 0.8 | L16: 0.18 | Y16: 松土器时间利用率 | Z16: 0.7 | AA16: 松土B10；折断/换齿/退车多，0.60~0.75
A17: 单人日装药能力 | B17: 100 | C17: kg/工日 | D17: 6 | E17: 1.05 | F17: 0.52 | G17: 0.78 | H17: 0.55 | I17: 0.88 | J17: 0.25 | K17: 0.75 | L17: 0.2 | Y17: 破碎锤时间利用率 | Z17: 0.65 | AA17: 破碎B10；散热/钎杆更换频繁，0.55~0.70
A18: 年工作台班 | B18: 250 | C18: 台班 | D18: 8 | E18: 0.95 | F18: 0.6 | G18: 0.75 | H18: 0.4 | I18: 0.85 | J18: 0.12 | K18: 0.7 | L18: 0.22 | Y18: 直接开挖装车效率系数 | Z18: 1 | AA18: 挖装B15；岩石原状致密=1.0
A19: 保险费率 | B19: 0.003 | C19: — | D19: 10 | E19: 0.8 | F19: 0.67 | G19: 0.7 | H19: 0.25 | I19: 0.8 | J19: 0.08 | K19: 0.68 | L19: 0.24 | Y19: 爆破后装车效率系数 | Z19: 1.4 | AA19: 挖装B15；岩石松散好装=1.4
A20: 税率 | B20: 0.09 | C20: 增值税 | D20: 14 | E20: 0.6 | F20: 0.74 | G20: 0.62 | H20: 0.08 | I20: 0.7 | J20: 0.04 | K20: 0.65 | L20: 0.26 | Y20: 直接开挖满斗系数 | Z20: 1.05 | AA20: 挖装B19；原状岩斗略冒尖=1.05
A21: 工作面折减系数 | B21: 0.95 | C21: — | D21: 18 | E21: 0.5 | F21: 0.85 | G21: 0.55 | H21: 0 | I21: 0.6 | J21: 0.02 | K21: 0.63 | L21: 0.28 | Y21: 爆破后满斗系数 | Z21: 1.1 | AA21: 挖装B19；爆破块度均匀=1.10
A22: 警戒排险费 | B22: 0.5 | C22: 元/方 | D22: 22 | E22: 0.42 | F22: 1 | G22: 0.5 | H22: 0 | I22: 0.5 | J22: 0.01 | K22: 0.6 | L22: 0.3 | Y22: 松土/破碎斗容利用率 | Z22: 0.85 | AA22: 松土B10/破碎B10；钩头/锤头不同于挖斗，按0.85打折
Y23: 重力加速度g(m/s²) | Z23: 9.81 | AA23: ⚠已废弃（V8删提升高程H后无任何公式引用）：原为重力加速度g，用于爬坡功W=m·g·H
A24: 【挖掘机设备参数】 | Y24: 柴油低位热值(MJ/L) | Z24: 35.86 | AA24: ⚠已废弃（V8删提升高程H后无任何公式引用）：原为0号柴油标准热值，用于爬坡能耗折算
A25: 设备代号 | B25: 品牌 | C25: 型号 | D25: 斗容(m³) | E25: 工作重量(t) | F25: 动力类型 | G25: 功率(kW) | H25: 小时消耗量(L或kWh) | I25: 定员 | J25: 原值(万元) | K25: 耐用台班 | L25: 残值率 | M25: 租赁单价(元/台班) | N25: 斗齿单价(元) | O25: 斗齿寿命(h) | Y25: 坡度上坡油耗修正系数 | Z25: 0.06 | AA25: ⚠已废弃（V8删提升高程H后无任何公式引用）：原为柴油机爬坡综合效率
A26: W1.6 | B26: 三一 | C26: SY365H | D26: 1.6 | E26: 36.5 | F26: 柴油 | G26: 212 | H26: 14 | I26: 1 | J26: 85 | K26: =250*$Z$9 | L26: 0.1 | M26: 1650 | N26: 200 | O26: 800 | Y26: 坡度下坡油耗修正系数 | Z26: 0.03 | AA26: ⚠已废弃（V8删提升高程H后无任何公式引用）：原为电机爬坡综合效率
A27: W2.0 | B27: 卡特彼勒 | C27: 336D | D27: 2 | E27: 34 | F27: 柴油 | G27: 200 | H27: 16 | I27: 1 | J27: 120 | K27: =250*$Z$9 | L27: 0.1 | M27: 2000 | N27: 250 | O27: 750 | Y27: 缓冲孔附加成本系数 | Z27: 0.15
A28: W2.5 | B28: 小松 | C28: PC360 | D28: 2.5 | E28: 36 | F28: 柴油 | G28: 196 | H28: 18 | I28: 1 | J28: 160 | K28: =250*$Z$9 | L28: 0.1 | M28: 2100 | N28: 300 | O28: 700 | Y28: 坡面角修正基准角 | Z28: 75
A29: W3.2 | B29: 沃尔沃 | C29: EC480 | D29: 3.2 | E29: 48 | F29: 柴油 | G29: 265 | H29: 22 | I29: 1 | J29: 220 | K29: =250*$Z$9 | L29: 0.1 | M29: 2900 | N29: 350 | O29: 650 | Y29: 坡面角单耗修正系数 | Z29: 0.008
A30: E2.0 | B30: 三一 | C30: SY365E | D30: 2 | E30: 36.5 | F30: 电动 | G30: 212 | H30: 12.5 | I30: 1 | J30: 160 | K30: =250*$Z$9 | L30: 0.1 | M30: 2200 | N30: 250 | O30: 750 | Y30: 台阶高度修正基准m | Z30: 10
A31: W4.5 | B31: 三一 | C31: SY705H-S | D31: 4.5 | E31: 70 | F31: 柴油 | G31: 350 | H31: 26 | I31: 1 | J31: 250 | K31: =250*$Z$9 | L31: 0.1 | M31: 3500 | N31: 400 | O31: 600 | Y31: 台阶高度单耗修正系数 | Z31: 0.015
A32: W5.5 | B32: 三一 | C32: SY870H-S | D32: 5.5 | E32: 85 | F32: 柴油 | G32: 382 | H32: 30 | I32: 1 | J32: 420 | K32: =250*$Z$9 | L32: 0.1 | M32: 6300 | N32: 450 | O32: 550
A33: W6.5 | B33: 徐工 | C33: XE1050 | D33: 6.5 | E33: 105 | F33: 柴油 | G33: 420 | H33: 34 | I33: 1 | J33: 520 | K33: =250*$Z$9 | L33: 0.1 | M33: 8200 | N33: 500 | O33: 500
A34: W8.0 | B34: 太重 | C34: TZ1000 | D34: 8 | E34: 100 | F34: 柴油 | G34: 510 | H34: 40 | I34: 1 | J34: 650 | K34: =250*$Z$9 | L34: 0.1 | M34: 8500 | N34: 550 | O34: 450
A35: E6.5 | B35: 太重 | C35: TZ1000E | D35: 6.5 | E35: 105 | F35: 电动 | G35: 420 | H35: 26.25 | I35: 1 | J35: 680 | K35: =250*$Z$9 | L35: 0.1 | M35: 8000 | N35: 500 | O35: 500
A36: E8.0 | B36: 沃尔沃 | C36: EC1500E | D36: 8 | E36: 150 | F36: 电动 | G36: 630 | H36: 35 | I36: 1 | J36: 850 | K36: =250*$Z$9 | L36: 0.1 | M36: 9500 | N36: 550 | O36: 450
A38: 【矿用运输车参数】 | R38: 【坡度对速度及油耗/电耗修正系数】 | Y38: 说明：R40:R44是按方向×坡度区间的通用系数表，与矿卡型号无关；故矿卡参数表R45:R47行该区域留空。
A39: 设备代号 | B39: 品牌 | C39: 型号 | D39: 载重(t) | E39: 动力类型 | F39: 功率(kW) | G39: 空载消耗每车(L/km或kWh/km) | H39: 重载上坡油耗(L/km或kWh/km) | I39: 重载下坡油耗(L/km或kWh/km) | J39: 定员 | K39: 原值(万元) | L39: 耐用总台班(年250台班，8年折旧） | M39: 残值率 | N39: 租赁单价(元/台班) | O39: 空车速度(km/h) | P39: 重车速度(km/h) | Q39: 卸车时间(min) | R39: 方向 | S39: 坡度下限(%) | T39: 坡度上限(%) | U39: 空车速度系数 | V39: 重车速度系数 | W39: 柴油油耗系数 | X39: 电动电耗系数 | Y39: ⚠待核：W列油耗系数的"基准坡度"语义需明确——当前W41=W40=1隐含中坡基准
A40: T30H | B40: 中国重汽 | C40: 豪沃TX 8×4 | D40: 30 | E40: 柴油 | F40: 257 | G40: 0.5 | H40: 1.75 | I40: =G40*1.05 | J40: 1 | K40: 35 | L40: =250*$Z$8 | M40: 0.1 | N40: 700 | O40: 35 | P40: 25 | Q40: 1 | R40: 平路 | S40: 0 | T40: 1.99 | U40: 1 | V40: 1 | W40: 1 | X40: 1
A41: E30S | B41: 三一重工 | C41: C8 350kWh 8×4 | D41: 31 | E41: 纯电 | F41: 405 | G41: 0.5 | H41: 1.8 | I41: =G41*1.05 | J41: 1 | K41: 62 | L41: =250*$Z$8 | M41: 0.1 | N41: 1500 | O41: 35 | P41: 25 | Q41: 1 | R41: 上坡 | S41: 2 | T41: 7.99 | U41: 0.85 | V41: 0.75 | W41: 1 | X41: 2.2
...

Sheet 合理建议表-推荐规则
A1: 工艺设备推荐表
A2: f下限 | B2: f上限 | C2: 推荐工艺 | D2: 推荐挖机 | E2: 短途矿卡(<3km) | F2: 中途矿卡(3-8km) | G2: 长途矿卡(>8km) | H2: 推荐钻机 | I2: 推荐孔径 | J2: 电动矿卡 | K2: 柴油矿卡
A3: 0 | B3: 0.9 | C3: 直接开挖 | D3: W2.5 | E3: T30H | F3: T30H | G3: T30H | H3: — | I3: — | J3: — | K3: T30H
A4: 1 | B4: 3.9 | C4: 松土器松土+开挖 | D4: W3.2 | E4: T30H | F4: T30H | G4: T65B | H4: — | I4: — | J4: — | K4: T30H
A5: 4 | B5: 5.9 | C5: 爆破+开挖 | D5: W4.5 | E5: T65B | F5: T65B | G5: T91B | H5: ZG90 | I5: 90 | J5: E60Y | K5: T65B
A6: 6 | B6: 7.9 | C6: 爆破+开挖 | D6: W5.5 | E6: T91B | F6: T91B | G6: T91B | H6: AC90 | I6: 90 | J6: E75T | K6: T91B
A7: 8 | B7: 13.9 | C7: 爆破+开挖 | D7: W6.5 | E7: T91B | F7: T91B | G7: T91B | H7: AC120 | I7: 115 | J7: E93L | K7: T91B
A8: 14 | B8: 22 | C8: 爆破+开挖 | D8: W8.0 | E8: T91B | F8: T91B | G8: T91B | H8: AC120 | I8: 115 | J8: E93L | K8: T91B

Sheet 计算明细表-钻爆成本
A1: 钻孔成本计算明细表
A2: 最终爆破成本(元/方) | B2: =B17+B37 | C2: 总爆破成本 = 主爆破费(B17) + 预裂附加费(B37)
A3: 工艺判断 | B3: =IF(ISBLANK('成本汇总-测算主表'!$B$12),"请选择工艺",IF(OR('成本汇总-测算主表'!$B$12="直接开挖",'成本汇总-测算主表'!$B$12="松土器松土+开挖",'成本汇总-测算主表'!$B$12="机械破碎+开挖"),"不适用","正常计算")) | C3: 工艺判断：非"爆破"类工艺时，钻爆所有项归零
A4: --- 单方爆破费用计算明细 ---
A5: 炸药费(元/方) | B5: =IF(OR(B3="不适用",B3="请选择工艺"),0,IFERROR(B56/B72*'基础核心-参数库'!$B$6,0))
A6: 雷管费(元/方) | B6: =IF(OR(B3="不适用",B3="请选择工艺"),0,IFERROR('基础核心-参数库'!$B$7/B72,0)) | C6: 雷管费 = 雷管单价(参数库B7)÷每孔体积；按每孔1发雷管计
A7: 导爆索费(元/方) | B7: =IF(OR(B3="不适用",B3="请选择工艺"),0,IFERROR('基础核心-参数库'!$B$8*B69/B72,0)) | C7: 导爆索费 = 导爆索单价(B8)×孔深(B69)÷每孔体积
A8: 单人日装药孔数 | B8: =IF(OR(B3="不适用",B3="请选择工艺"),0,IFERROR('基础核心-参数库'!$B$17/B56,0)) | C8: 单人日装药孔数 = 单人日装药能力(B17)÷代表单孔药量(B56)
A9: 每日爆破方量 | B9: =B8*B72 | C9: 每日爆破方量 = 日装药孔数(B8) × 每孔体积(B72)
A10: 装药人工费(元/方) | B10: =IF(OR(B3="不适用",B3="请选择工艺"),0,IFERROR('基础核心-参数库'!$B$16/B9,0)) | C10: 装药人工费 = 爆破工日工资(B16)÷每日方量(B9)
A11: 装载机折旧(元/台班) | B11: =IF(OR(B3="不适用",B3="请选择工艺"),0,('基础核心-参数库'!$B$101*10000*(1-'基础核心-参数库'!$B$103)/'基础核心-参数库'!$B$102)*'基础核心-参数库'!$Z$6) | C11: 装载机折旧维修=原值(B101)×(1-残值率B103)÷耐用台班(B102)×系数【常量Z6=1.5】
A12: 装载机能源(元/台班) | B12: =IF(OR(B3="不适用",B3="请选择工艺"),0,'基础核心-参数库'!$B$100*'基础核心-参数库'!$Z$10*'基础核心-参数库'!$B$3/'基础核心-参数库'!$Z$11) | C12: 装载机能源=小时油耗(B100)×台班小时【常量Z10=8】×柴油单价(B3)÷柴油效率【常量Z11=0.75】
A13: 装载机保险(元/台班) | B13: =IF(OR(B3="不适用",B3="请选择工艺"),0,'基础核心-参数库'!$B$101*10000*'基础核心-参数库'!$B$19/'基础核心-参数库'!$B$18) | C13: 装载机保险=原值×保险费率(B19)÷年台班(B18)
A14: 装载机台班费(元) | B14: =B11+B12+B13 | C14: 装载机台班费 = 折旧维修+能源+保险
A15: 装载机辅助费(元/方) | B15: =IF(OR(B3="不适用",B3="请选择工艺"),0,IFERROR(B14*'基础核心-参数库'!$B$105/B9,0)) | C15: 装载机辅助费 = 台班费×台班利用系数(B105)÷服务方量
A16: 警戒排险费(元/方) | B16: =IF(OR(B3="不适用",B3="请选择工艺"),0,'基础核心-参数库'!$B$22) | C16: 警戒排险费：参数库B22默认0.5元/方
A17: 主爆破费(元/方) | B17: =IF(OR(B3="不适用",B3="请选择工艺"),0,(B103+B5+B6+B7+B10+B15+B16)*(1+B22*'基础核心-参数库'!$Z$27)) | C17: 主爆破费 = (钻机摊销+炸药+雷管+索+装药人工+装载机辅助+警戒) × (1 + 缓冲孔排数×Z27=0.15)
A19: --- 预裂爆破计算明细 ---
A20: 爆破长度 L(m) | B20: ='成本汇总-测算主表'!$B$44 | C20: 场地长度 = 主表B44：沿台阶走向的一次爆破长度
A21: 爆破宽度 W(m) | B21: ='成本汇总-测算主表'!$B$45 | C21: 场地宽度 = 主表B45
A22: 缓冲孔排数 | B22: ='成本汇总-测算主表'!$B$46 | C22: 缓冲孔排数 = 主表B46
A23: 预裂孔孔距(m) | B23: =IF(B47="是",IFERROR(SUMIFS('基础核心-参数库'!$G$109:$G$113,'基础核心-参数库'!$E$109:$E$113,"<="&'成本汇总-测算主表'!$B$5,'基础核心-参数库'!$F$109:$F$113,">"&'成本汇总-测算主表'!$B$5)*B49/1000,10*B49/1000),0) | C23: 预裂孔距(m) = SUMIFS按f值查参数库 E109:G113 的孔距系数K × 缓冲排数 ÷ 1000
A24: 预裂孔数量 | B24: =IF(AND(B47="是",B20>0),ROUNDUP(B20/B23,0),0) | C24: 预裂孔数量 = ROUNDUP(场地长度÷预裂孔距)
A25: 预裂单孔钻孔费 | B25: =IF(B47="是",B102*(B40+'基础核心-参数库'!$B$112),0) | C25: 预裂单孔钻孔费 = 钻机每米费(B102)×(台阶高+超钻)
A26: 预裂单孔装药费 | B26: =IF(B47="是",'基础核心-参数库'!$B$110*B20*'基础核心-参数库'!$B$6+'基础核心-参数库'!$B$113*'基础核心-参数库'!$B$110*'基础核心-参数库'!$B$112*'基础核心-参数库'!$B$6,0) | C26: 预裂单孔装药费 = 预裂线装药密度(B110)×台阶高×炸药单价
A27: 预裂单孔雷管费 | B27: =IF(B47="是",'基础核心-参数库'!$B$114*'基础核心-参数库'!$B$7,0) | C27: 预裂单孔雷管费 = 雷管发数(B114)×雷管单价
A28: 预裂单孔总费用 | B28: =B25+B26+B27 | C28: 预裂单孔总费 = 钻孔+装药+雷管
A29: 预裂总费用 | B29: =B24*B28 | C29: 预裂总费用 = 单孔费(B28) × 孔数(B24)
A30: 缓冲孔孔距(m) | B30: =B69*'基础核心-参数库'!$I$110 | C30: 缓冲孔孔距 = 孔距a(B69)×缓冲孔系数(参数库I110)
A31: 缓冲孔排距(m) | B31: =B70*'基础核心-参数库'!$I$111 | C31: 缓冲孔排距 = 排距b(B70)×缓冲孔系数(I111)
A32: 缓冲孔数量 | B32: =IF(AND(B47="是",B22>0,B20>0),ROUNDUP(B20/B30,0)*B22,0) | C32: 缓冲孔数量 = ROUNDUP(长度÷孔距)×排数
A33: 单孔缓冲钻孔费 | B33: =IF(B47="是",B102*B67,0) | C33: 缓冲单孔钻孔费 = 钻机每米费×孔深
A34: 单孔缓冲装药费 | B34: =IF(B47="是",B56*'基础核心-参数库'!$I$109*'基础核心-参数库'!$B$6,0) | C34: 缓冲单孔装药费 = 单耗(B56)×系数(I109)×炸药单价
A35: 单孔缓冲总费用 | B35: =B33+B34 | C35: 缓冲单孔总费 = 钻孔+装药
A36: 缓冲孔总费用 | B36: =B32*B35 | C36: 缓冲孔总费用 = 单孔费 × 孔数
A37: 预裂附加费(元/方) | B37: =IF(AND(B47="是",B20>0,B21>0,'成本汇总-测算主表'!$B$47>0),(B29+B36)/(B20*B21*'成本汇总-测算主表'!$B$47),0) | C37: 预裂附加费(元/方) = (预裂总费+缓冲总费)÷影响范围方量
A39: --- 作业面基本参数汇集 ---
A40: 台阶高度H(m) | B40: ='成本汇总-测算主表'!$B$47 | C40: 台阶高度 = 主表B47
A41: 坡面角α(°) | B41: ='成本汇总-测算主表'!$B$48 | C41: 坡面角 = 主表B48
A42: 钻孔倾角(°) | B42: ='成本汇总-测算主表'!$B$49 | C42: 钻孔倾角 = 主表B49
...

Sheet 计算明细表-挖装成本
A1: 开挖装车成本计算明细表
A2: 开挖费(元/实方) | B2: =IFERROR(B35/B23,0) | C2: 挖机台班费÷台班产量实方
A3: 工艺判断 | B3: =IF(ISBLANK('成本汇总-测算主表'!$B$12),"请选择工艺",'成本汇总-测算主表'!$B$12) | C3: 工艺类型：从主表B12读取
A5: --- 基本参数 ---
A6: f值 | B6: ='成本汇总-测算主表'!$B$5 | C6: f值：从主表B5读取
A7: 松散系数 | B7: ='成本汇总-测算主表'!$B$7 | C7: 松散系数：直接引用主表B7（保证手动覆盖时联动）
A8: 挖机代号 | B8: ='成本汇总-测算主表'!$B$17 | C8: 挖机代号：从主表B17读取
A9: 挖机来源 | B9: ='成本汇总-测算主表'!$B$18 | C9: 挖机来源：从主表B18读取
A10: 斗容(m³) | B10: =IFERROR(VLOOKUP(B8,'基础核心-参数库'!$A$26:$D$36,4,0),2) | C10: 斗容(m³)：按代号从参数库 D$26 查
A11: 工作重量(t) | B11: =IFERROR(VLOOKUP(B8,'基础核心-参数库'!$A$26:$E$36,5,0),20) | C11: 工作重量(t)：按代号查参数库 E$26（影响保险/吨油耗类间接核算）
A12: 动力类型 | B12: =IFERROR(VLOOKUP(B8,'基础核心-参数库'!$A$26:$F$36,6,0),"柴油") | C12: 动力类型：参数库 F$26 查
A13: 小时消耗 | B13: =IFERROR(VLOOKUP(B8,'基础核心-参数库'!$A$26:$H$36,8,0),20) | C13: 小时油耗(L/h)或耗电(kWh/h)：按代号查参数库 H$26
A14: 机械效率 | B14: =IF(B12="柴油",'基础核心-参数库'!$Z$11,'基础核心-参数库'!$Z$12) | C14: 机械效率：柴油=【常量Z11=0.75】，电=【Z12=0.85】
A15: 工艺类型装车效率系数 | B15: =IF(B3="直接开挖",'基础核心-参数库'!$Z$18,'基础核心-参数库'!$Z$19) | C15: 装车效率：直接开挖【Z18=1.0】，爆破后岩石松散【Z19=1.4】
A16: 岩石硬度与挖掘循环时间修正系数 | B16: =1+MAX(0,B6-5)*0.02 | C16: f=5（Ⅳ级中硬岩）是绝大多数露天矿山的典型工况。f≤5时，常规挖机可以正常高效作业，无需修正；f>5时，岩石越硬，挖掘循环时间越长，需要修正。f每增加1，挖掘斗杆插入阻力增加约5~8%，但通过操作技巧（分层挖掘、慢速作业），实际效率下降约2%。
A18: 台班工程量计算
A19: 工艺类型满斗系数 | B19: =IF(B3="直接开挖",'基础核心-参数库'!$Z$20,'基础核心-参数库'!$Z$21) | C19: 满斗系数：直接开挖【Z20=1.05】，爆破后块度均匀【Z21=1.10】
A20: 基准循环时间(秒) | B20: =IFERROR(4.158*LN(B11*1000)-25.058+MAX(0,(B11-30))*0.2,20) | C20: 装载循环时间(秒)=4.158×LN(工作重量×1000)-25.058 + MAX(0,工作重量-30)×0.2【30吨以上每吨加0.2秒，覆盖大机回转/对位时间】
A21: 循环时间(秒) | B21: =B20*B16*B15 | C21: 工艺时间修正 = 装载循环时间(B20)×松散修正(B15)×f值修正(B16)
A22: 台班产量松方(m³) | B22: =B10*B19*(3600/B21)*'基础核心-参数库'!$Z$10*'基础核心-参数库'!$Z$14*'基础核心-参数库'!$B$21 | C22: 台班产量(松方) = 斗容×满斗×(3600÷循环时间)×台班小时【Z10=8】×挖机时间利用率【Z14=0.80】×工作面折减
A23: 台班产量实方(m³) | B23: =B22/B7 | C23: 台班产量(松方) = 实方 × 松散系数
A25: 台班总成本计算
A26: 原值(万元) | B26: =IFERROR(VLOOKUP(B8,'基础核心-参数库'!$A$26:$J$36,10,0),0) | C26: 原值(万元)：参数库 J$26 查
A27: 耐用台班 | B27: =IFERROR(VLOOKUP(B8,'基础核心-参数库'!$A$26:$K$36,11,0),4000) | C27: 耐用台班：参数库 K$26 查 (=250×常量Z9=2500)
A28: 折旧+维修费(元/台班) | B28: =(B26*10000*(1-IFERROR(VLOOKUP(B8,'基础核心-参数库'!$A$26:$L$36,12,0),0.05))/B27)*'基础核心-参数库'!$Z$4 | C28: 挖机折旧维修=原值(J$26)×(1-残值率L$26)÷耐用台班(K$26)×系数【常量Z4=1.6】
A29: 能源费(元/台班) | B29: =B13*'基础核心-参数库'!$Z$10*IF(B12="柴油",'基础核心-参数库'!$B$3,'基础核心-参数库'!$B$4)/B14 | C29: 挖机能源=小时油耗×台班小时【Z10=8】×单价÷效率
A30: 保险费(元/台班) | B30: =B26*10000*'基础核心-参数库'!$B$19/'基础核心-参数库'!$B$18 | C30: 挖机保险=原值×保险率÷年台班
A31: 人工费(元/台班) | B31: ='基础核心-参数库'!$B$5 | C31: 挖机机手 = 参数库B5(=300元/工日)
A32: 斗齿耗材费(元/台班) | B32: =IFERROR(VLOOKUP(B8,'基础核心-参数库'!$A$26:$N$36,14,0)*8/VLOOKUP(B8,'基础核心-参数库'!$A$26:$O$36,15,0),0) | C32: 斗齿耗材费(元/台班) = 斗齿单价(N$26) × 台班小时【Z10=8】 ÷ 斗齿寿命(O$26,单位h)
A33: 自有台班费(元) | B33: =B28+B29+B30+B31+B32 | C33: 挖机自有台班费 = 折旧+能源+保险+机手+辅助
A34: 租赁台班费(元) | B34: =MAX(IFERROR(VLOOKUP(B8,'基础核心-参数库'!$A$26:$M$36,13,0),0),B33*1.05) | C34: 挖机租赁台班费 = MAX(参数库 M$26 查, 自有费 B33 × 1.05) ←v10兜底防倒挂
A35: 台班费(元) | B35: =IF(B9="自有",B33,B34) | C35: 台班费 = 自有则取自有费，否则取租赁费

Sheet 计算明细表-运输成本
A1: 运输成本计算明细表
A2: 运输费(元/实方) | B2: =IF(AND(B23=0,B24=0),0,IFERROR(B74/B51,0)) | C2: 台班费÷台班运输量（运距为0时运输费=0）
A4: --- 基本参数汇集 ---
A5: f值 | B5: ='成本汇总-测算主表'!$B$5 | C5: f值：主表B5
A6: 实体容重(t/m³) | B6: ='成本汇总-测算主表'!$B$6 | C6: 实体容重：主表B6
A7: 矿卡代号 | B7: ='成本汇总-测算主表'!$B$23 | C7: 矿卡代号：主表B23
A8: 矿卡来源 | B8: ='成本汇总-测算主表'!$B$24 | C8: 矿卡来源：主表B24
A9: 矿卡载重(t) | B9: =IFERROR(VLOOKUP(B7,'基础核心-参数库'!$A$40:$D$47,4,0),45) | C9: 矿卡载重(t)：参数库 D$40 按代号查
A10: 动力类型 | B10: =IFERROR(VLOOKUP(B7,'基础核心-参数库'!$A$40:$E$47,5,0),"柴油") | C10: 动力类型：参数库 E$40 查
A11: 空载消耗(L/km或kWh/km) | B11: =IFERROR(VLOOKUP(B7,'基础核心-参数库'!$A$40:$G$47,7,0),0.25) | C11: 空载油耗/电耗：参数库 G$40 查
A12: 重载上坡消耗(L/km或kWh/km) | B12: =IFERROR(VLOOKUP(B7,'基础核心-参数库'!$A$40:$H$47,8,0),0.55) | C12: 重载上坡油耗/电耗：参数库 H$40 查
A13: 重载下坡消耗(L/km或kWh/km) | B13: =IFERROR(VLOOKUP(B7,'基础核心-参数库'!$A$40:$I$47,9,0),0.55) | C13: 重载下坡油耗/电耗：按代号查参数库 I$40
A14: 空车速度(km/h) | B14: =IFERROR(VLOOKUP(B7,'基础核心-参数库'!$A$40:$O$47,15,0),30) | C14: 空车速度：参数库 O$40 查
A15: 重车速度(km/h) | B15: =IFERROR(VLOOKUP(B7,'基础核心-参数库'!$A$40:$P$47,16,0),20) | C15: 重车速度：参数库 P$40 查
A16: 卸车时间(min) | B16: =IFERROR(VLOOKUP(B7,'基础核心-参数库'!$A$40:$Q$47,17,0),1.5) | C16: 卸车时间：参数库 Q$40 查
A17: 机械效率 | B17: =IF(B10="柴油",'基础核心-参数库'!$Z$11,'基础核心-参数库'!$Z$12) | C17: 机械效率：柴油=【常量Z11=0.75】，电=【Z12=0.85】
A18: 每车实方(m³) | B18: =IFERROR(B9/'成本汇总-测算主表'!$B$6,0) | C18: 车辆载重除以实体容重
A19: 挖机松方产量(m³/台班) | B19: ='计算明细表-挖装成本'!$B$22 | C19: 挖机松方台班产量：从挖装表 B22 取
A20: 装车时间(min) | B20: =ROUNDUP(B18*'计算明细表-挖装成本'!$B$7/('计算明细表-挖装成本'!$B$10*'计算明细表-挖装成本'!$B$19),0)*'计算明细表-挖装成本'!$B$21/60 | C20: 装车时间(min) = 每车实方×松散系数÷(挖机实方/秒×装满系数)×循环时间÷60
A22: --- 运距参数汇集 ---
A23: 场内距离(km) | B23: ='成本汇总-测算主表'!$B$34 | C23: 场内距离：主表B34
A24: 场外距离(km) | B24: ='成本汇总-测算主表'!$B$35 | C24: 场外距离：主表B35
A25: 场内重车方向 | B25: ='成本汇总-测算主表'!$B$37 | C25: 场内重车方向：主表B37
A26: 场内坡度(%) | B26: ='成本汇总-测算主表'!$B$38 | C26: 场内坡度：主表B38
A27: 场外重车方向 | B27: ='成本汇总-测算主表'!$B$39 | C27: 场外重车方向：主表B39
A28: 场外坡度(%) | B28: ='成本汇总-测算主表'!$B$40 | C28: 场外坡度：主表B40
A29: 场内空车方向 | B29: =IF(B25="上坡","下坡",IF(B25="下坡","上坡","平路")) | C29: 场内空车方向：与重车方向相反
A30: 场外空车方向 | B30: =IF(B27="上坡","下坡",IF(B27="下坡","上坡","平路")) | C30: 场外空车方向：与重车方向相反
A32: --- 速度修正系数 ---
A33: 场内系数
A34: 场内重车速度系数 | B34: =MAX(IFERROR(SUMIFS('基础核心-参数库'!$V$40:$V$44,'基础核心-参数库'!$R$40:$R$44,B25,'基础核心-参数库'!$S$40:$S$44,"<="&B26,'基础核心-参数库'!$T$40:$T$44,">"&B26),0),IF(B25="平路",1,IF(B25="上坡",0.75,0.9))) | C34: 场内重车速度系数：SUMIFS按方向+坡度区间查 V$40:V$44
A35: 场内空车速度系数 | B35: =MAX(IFERROR(SUMIFS('基础核心-参数库'!$U$40:$U$44,'基础核心-参数库'!$R$40:$R$44,B29,'基础核心-参数库'!$S$40:$S$44,"<="&B26,'基础核心-参数库'!$T$40:$T$44,">"&B26),0),IF(B29="平路",1,IF(B29="上坡",0.85,1.05))) | C35: 场内空车速度系数：SUMIFS查 U$40:U$44
A36: 场外重车速度系数 | B36: =MAX(IFERROR(SUMIFS('基础核心-参数库'!$V$40:$V$44,'基础核心-参数库'!$R$40:$R$44,B27,'基础核心-参数库'!$S$40:$S$44,"<="&B28,'基础核心-参数库'!$T$40:$T$44,">"&B28),0),IF(B27="平路",1,IF(B27="上坡",0.75,0.9))) | C36: 场外重车速度系数：同上查 V列
A37: 场外空车速度系数 | B37: =MAX(IFERROR(SUMIFS('基础核心-参数库'!$U$40:$U$44,'基础核心-参数库'!$R$40:$R$44,B30,'基础核心-参数库'!$S$40:$S$44,"<="&B28,'基础核心-参数库'!$T$40:$T$44,">"&B28),0),IF(B30="平路",1,IF(B30="上坡",0.85,1.05))) | C37: 场外空车速度系数：同上查 U列
A38: 场外系数
A39: 场内重车速度(km/h) | B39: =B15*B34 | C39: 场内重车实际速度 = 重车速度(B15) × 系数(B34)
A40: 场内空车速度(km/h) | B40: =B14*B35 | C40: 场内空车实际速度 = 空车速度(B14) × 系数(B35)
A41: 场外重车速度(km/h) | B41: =B15*B36 | C41: 场外重车实际速度 = 重车速度 × 系数(B36)
A42: 场外空车速度(km/h) | B42: =B14*B37 | C42: 场外空车实际速度 = 空车速度 × 系数(B37)
A44: --- 台班方量计算 ---
...

Sheet 计算明细表-钩机松土成本
A1: 钩机松土成本计算明细表
A2: 松土费(元/实方) | B2: =IFERROR(B11/B10+B12,0) | C2: 松土费 = 挖机台班费÷松土器台班产量 + 齿尖耗材费
A3: f值 | B3: ='成本汇总-测算主表'!$B$5 | C3: f值：主表B5
A4: 挖机代号 | B4: ='成本汇总-测算主表'!$B$17 | C4: 挖机代号：主表B17
A5: 挖机来源 | B5: ='成本汇总-测算主表'!$B$18 | C5: 挖机来源：主表B18
A6: 斗容(m³) | B6: =IFERROR(VLOOKUP(B4,'基础核心-参数库'!$A$26:$D$36,4,0),2) | C6: 斗容(m³)：按代号查参数库 D$26
A7: 岩石硬度松土器作业效率系数 | B7: {=IFERROR(IF(B3<='基础核心-参数库'!$D$13,INDEX('基础核心-参数库'!$H$13:$H$22,MATCH('基础核心-参数库'!$D$13,'基础核心-参数库'!$D$13:$D$22,0)),IF(B3>='基础核心-参数库'!$D$22,INDEX('基础核心-参数库'!$H$13:$H$22,MATCH('基础核心-参数库'!$D$22,'基础核心-参数库'!$D$13:$D$22,0)),INDEX('基础核心-参数库'!$H$13:$H$22,MATCH(B3,'基础核心-参数库'!$D$13:$D$22,1))+(B3-INDEX('基础核心-参数库'!$D$13:$D$22,MATCH(B3,'基础核心-参数库'!$D$13:$D$22,1)))*(INDEX('基础核心-参数库'!$H$13:$H$22,MATCH(B3,'基础核心-参数库'!$D$13:$D$22,1)+1)-INDEX('基础核心-参数库'!$H$13:$H$22,MATCH(B3,'基础核心-参数库'!$D$13:$D$22,1)))/(INDEX('基础核心-参数库'!$D$13:$D$22,MATCH(B3,'基础核心-参数库'!$D$13:$D$22,1)+1)-INDEX('基础核心-参数库'!$D$13:$D$22,MATCH(B3,'基础核心-参数库'!$D$13:$D$22,1))))),0)} | C7: 松土器效率系数：f值插值，2~0，f越大效率越低，f>14时松土器基本失效。
A8: 工艺顺序错配惩罚系数（松土器） | B8: =IFERROR(IF(AND('成本汇总-测算主表'!$B$13="爆破+开挖",'成本汇总-测算主表'!$B$12="松土器松土+开挖"),VLOOKUP("爆破→松土",'基础核心-参数库'!$M$3:$O$7,2,0),IF(AND('成本汇总-测算主表'!$B$13="松土器松土+开挖",'成本汇总-测算主表'!$B$12="机械破碎+开挖"),VLOOKUP("松土→破碎",'基础核心-参数库'!$M$3:$O$7,2,0),1)),1) | C8: 工艺错配惩罚：爆破→松土 ×0.2（极不推荐）；松土→破碎 ×0.7（勉强可接受）。
A9: 工艺错配齿尖消耗倍率 | B9: =IFERROR(IF(AND('成本汇总-测算主表'!$B$13="爆破+开挖",'成本汇总-测算主表'!$B$12="松土器松土+开挖"),VLOOKUP("爆破→松土",'基础核心-参数库'!$M$3:$O$7,3,0),IF(AND('成本汇总-测算主表'!$B$13="松土器松土+开挖",'成本汇总-测算主表'!$B$12="机械破碎+开挖"),VLOOKUP("松土→破碎",'基础核心-参数库'!$M$3:$O$7,3,0),1)),1) | C9: 耗材费倍率：工艺顺序错误时，齿尖消耗成倍增加，爆破→松土 ×5.0，松土→破碎 ×1.5。
A10: 松土器台班产量(实方) | B10: =IFERROR(B7*INDEX('基础核心-参数库'!$B$119:$B$124,MATCH(B3,'基础核心-参数库'!$A$119:$A$124,1))*(B6/2)*'基础核心-参数库'!$Z$22*'基础核心-参数库'!$Z$16*'基础核心-参数库'!$B$21,0)*B8 | C10: 松土器台班产量 = 工艺效率×松土斗系数×(斗容÷2)×斗容利用率【Z22=0.85】×松土器时间利用率【Z16=0.70】×工作面折减(B21)×错配惩罚
A11: 挖机台班费(元) | B11: ='计算明细表-挖装成本'!$B$35 | C11: 与开挖设备同型号，但更换了钩机头，故台班费用与所选挖机费用一致。
A12: 齿尖耗材费(元/方) | B12: =IFERROR('基础核心-参数库'!$B$12/'基础核心-参数库'!$B$13,0)*B9 | C12: 齿尖耗材费 = 齿尖单价(B12)÷寿命(B13) × 错配消耗倍率(B9)

Sheet 计算明细表-机械破碎成本
A1: 机械破碎成本计算明细表
A2: 破碎费(元/实方) | B2: =IFERROR(B11/B10+B12,0) | C2: 破碎费 = 挖机台班费÷破碎台班产量 + 钎杆耗材费
A3: f值 | B3: ='成本汇总-测算主表'!$B$5 | C3: f值：主表B5
A4: 挖机代号 | B4: ='成本汇总-测算主表'!$B$17 | C4: 挖机代号：主表B17
A5: 挖机来源 | B5: ='成本汇总-测算主表'!$B$18 | C5: 挖机来源：主表B18
A6: 斗容(m³) | B6: =IFERROR(VLOOKUP(B4,'基础核心-参数库'!$A$26:$D$36,4,0),2) | C6: 斗容(m³)：按代号查参数库 D$26
A7: 岩石硬度破碎锤作业效率系数 | B7: {=IFERROR(IF(B3<='基础核心-参数库'!$D$13,INDEX('基础核心-参数库'!$I$13:$I$22,MATCH('基础核心-参数库'!$D$13,'基础核心-参数库'!$D$13:$D$22,0)),IF(B3>='基础核心-参数库'!$D$22,INDEX('基础核心-参数库'!$I$13:$I$22,MATCH('基础核心-参数库'!$D$22,'基础核心-参数库'!$D$13:$D$22,0)),INDEX('基础核心-参数库'!$I$13:$I$22,MATCH(B3,'基础核心-参数库'!$D$13:$D$22,1))+(B3-INDEX('基础核心-参数库'!$D$13:$D$22,MATCH(B3,'基础核心-参数库'!$D$13:$D$22,1)))*(INDEX('基础核心-参数库'!$I$13:$I$22,MATCH(B3,'基础核心-参数库'!$D$13:$D$22,1)+1)-INDEX('基础核心-参数库'!$I$13:$I$22,MATCH(B3,'基础核心-参数库'!$D$13:$D$22,1))))),0)} | C7: 破碎锤效率系数：f值插值，1.2~0.5，f越大效率越低 比松土器适用范围更广（f到22仍有效）
A8: 工艺顺序错配惩罚系数（破碎锤） | B8: =IFERROR(IF(AND('成本汇总-测算主表'!$B$13="爆破+开挖",OR('成本汇总-测算主表'!$B$12="机械破碎+开挖",'成本汇总-测算主表'!$B$12="爆破+二次破碎+开挖")),VLOOKUP("爆破→破碎",'基础核心-参数库'!$M$3:$O$7,2,0),IF(AND('成本汇总-测算主表'!$B$13="松土器松土+开挖",OR('成本汇总-测算主表'!$B$12="机械破碎+开挖",'成本汇总-测算主表'!$B$12="爆破+二次破碎+开挖")),VLOOKUP("松土→破碎",'基础核心-参数库'!$M$3:$O$7,2,0),1)),1) | C8: 工艺错配惩罚：爆破→破碎 ×0.5（不推荐），松土→破碎 ×0.7（勉强可接受）
A9: 工艺错配钎杆消耗倍率 | B9: =IFERROR(IF(AND('成本汇总-测算主表'!$B$13="爆破+开挖",OR('成本汇总-测算主表'!$B$12="机械破碎+开挖",'成本汇总-测算主表'!$B$12="爆破+二次破碎+开挖")),VLOOKUP("爆破→破碎",'基础核心-参数库'!$M$3:$O$7,3,0),IF(AND('成本汇总-测算主表'!$B$13="松土器松土+开挖",OR('成本汇总-测算主表'!$B$12="机械破碎+开挖",'成本汇总-测算主表'!$B$12="爆破+二次破碎+开挖")),VLOOKUP("松土→破碎",'基础核心-参数库'!$M$3:$O$7,3,0),1)),1) | C9: 耗材费倍率：工艺顺序错误时，钎杆消耗成倍增加，爆破→破碎 ×3.0，松土→破碎 ×1.5。
A10: 破碎台班产量(实方) | B10: =IFERROR(B7*INDEX('基础核心-参数库'!$D$119:$D$124,MATCH(B3,'基础核心-参数库'!$C$119:$C$124,1))*(B6/2)*'基础核心-参数库'!$Z$22*'基础核心-参数库'!$Z$17*'基础核心-参数库'!$B$21,0)*B8 | C10: 破碎台班产量 = 工艺效率×破碎锤系数×(斗容÷2)×斗容利用率【Z22=0.85】×破碎锤时间利用率【Z17=0.65】×工作面折减(B21)×错配惩罚
A11: 挖机台班费(元) | B11: ='计算明细表-挖装成本'!$B$35 | C11: 挖机台班费 = 取挖装表B35（同挖机型号、换破碎锤）
A12: 钎杆耗材费(元/方) | B12: =IFERROR('基础核心-参数库'!$B$9/'基础核心-参数库'!$B$10,0)*B9 | C12: 钎杆耗材费 = 钎杆单价(B9)÷寿命(B10) × 错配消耗倍率
